Workbook

Sheet total mil euro
A1: Data extracted on 30/04/2026 21:21:12 from [ESTAT]
A2: Dataset: | C2: Environmental tax revenues [env_ac_tax__custom_21261132]
A3: Last updated: | C3: 10/02/2026 23:00
A5: Time frequency | C5: Annual
A6: Taxes | C6: Total environmental taxes
A7: Unit of measure | C7: Million euro
A9: TIME | B9: 1995 | C9: 1996 | D9: 1997 | E9: 1998 | F9: 1999 | G9: 2000 | H9: 2001 | I9: 2002 | J9: 2003 | K9: 2004 | L9: 2005 | M9: 2006 | N9: 2007 | O9: 2008 | P9: 2009 | Q9: 2010 | R9: 2011 | S9: 2012 | T9: 2013 | U9: 2014 | V9: 2015 | W9: 2016 | X9: 2017 | Y9: 2018 | Z9: 2019 | AA9: 2020 | AB9: 2021 | AC9: 2022 | AD9: 2023 | AE9: 2024
A10: European Union - 27 countries (from 2020) | B10: 163637.53 | C10: 175161.19 | D10: 177813.19 | E10: 186225.81 | F10: 199230.91 | G10: 203466.33 | H10: 212219.82 | I10: 221348.93 | J10: 231288.33 | K10: 241164.92 | L10: 249050.84 | M10: 258008.64 | N10: 264534.24 | O10: 267315.42 | P10: 266578.1 | Q10: 273355.06 | R10: 290990.94 | S10: 297600.15 | T10: 310953.86 | U10: 322701.67 | V10: 329560.57 | W10: 341554.87 | X10: 349286.72 | Y10: 355584.51 | Z10: 363045.78 | AA10: 334895.99 | AB10: 353649.87 | AC10: 340830.67 | AD10: 355996.78 | AE10: 374756.86
A11: Belgium | B11: 5303.99 | C11: 5851.04 | D11: 5945.31 | E11: 5985.54 | F11: 6283.8 | G11: 6167 | H11: 6320.6 | I11: 6401.6 | J11: 6796.2 | K11: 7518.3 | L11: 7855.7 | M11: 7658.6 | N11: 8023.2 | O11: 8081.1 | P11: 8188.5 | Q11: 8821.7 | R11: 9572.9 | S11: 9626.6 | T11: 9843.9 | U11: 10164.9 | V11: 10594.1 | W11: 11480.2 | X11: 11993.6 | Y11: 12381.1 | Z11: 12609.7 | AA11: 11602.6 | AB11: 12528.9 | AC11: 12390.7 | AD11: 13882.1 | AE11: 13723.8
A12: Bulgaria | B12: 174.5 | C12: 80.03 | D12: 116.03 | E12: 313.88 | F12: 314.86 | G12: 401.54 | H12: 394.85 | I12: 413.01 | J12: 526.89 | K12: 633.47 | L12: 712.49 | M12: 762.67 | N12: 1036.04 | O12: 1221.72 | P12: 1062.72 | Q12: 1051.59 | R12: 1107.78 | S12: 1118.55 | T12: 1200.93 | U12: 1220.67 | V12: 1351.73 | W12: 1451.15 | X12: 1468.89 | Y12: 1470.45 | Z12: 1839.12 | AA12: 1859.09 | AB12: 1978.67 | AC12: 4095.1 | AD12: 3176.22 | AE12: 3097.75
A13: Czechia | B13: 1205.44 | C13: 1297.33 | D13: 1252.16 | E13: 1299.15 | F13: 1426.74 | G13: 1511.42 | H13: 1762.01 | I13: 1979.81 | J13: 2068.61 | K13: 2335.42 | L13: 2708.41 | M13: 2950.22 | N13: 3198.7 | O13: 3643.79 | P13: 3427.58 | Q13: 3577.44 | R13: 3846.08 | S13: 3606.43 | T13: 3351.35 | U13: 3346.96 | V13: 3477.33 | W13: 3728.38 | X13: 3896.98 | Y13: 4129.14 | Z13: 4594.86 | AA13: 4148.06 | AB13: 4373.44 | AC13: 4076.53 | AD13: 4957.13 | AE13: 4641.24
A14: Denmark | B14: 6099.43 | C14: 6709.1 | D14: 6994.9 | E14: 8321.48 | F14: 8821.01 | G14: 8604.94 | H14: 8865.72 | I14: 9488.2 | J14: 9294.17 | K14: 10097.34 | L14: 10474.78 | M14: 10565.93 | N14: 11082.06 | O14: 10077.75 | P14: 9235.14 | Q14: 9768.48 | R14: 9956.58 | S14: 10095.62 | T14: 10683.28 | U14: 10651.75 | V14: 10846.5 | W14: 11082.03 | X14: 10790.34 | Y14: 10815.22 | Z14: 10246.59 | AA14: 9891.28 | AB14: 9703.62 | AC14: 8771.4 | AD14: 7734.8 | AE14: 8210.75
A15: Germany | B15: 42078.93 | C15: 42324.71 | D15: 41499.66 | E15: 41796.81 | F15: 46337 | G15: 50963 | H15: 56212 | I15: 57197 | J15: 61229 | K15: 60849 | L15: 60837 | M15: 62533 | N15: 62772 | O15: 64140 | P15: 66381 | Q15: 63845 | R15: 72185 | S15: 72621 | T15: 78210 | U15: 81776 | V15: 80837 | W15: 82463 | X15: 85260 | Y15: 84559 | Z15: 85723 | AA15: 82858 | AB15: 82001 | AC15: 73177 | AD15: 70791 | AE15: 75794
A16: Estonia | B16: 25.61 | C16: 52.67 | D16: 68.18 | E16: 95.41 | F16: 90.67 | G16: 104.39 | H16: 147.35 | I16: 154.59 | J16: 164.53 | K16: 203.87 | L16: 255.72 | M16: 295.95 | N16: 362.05 | O16: 396.75 | P16: 443.87 | Q16: 485.49 | R16: 500.55 | S16: 560.94 | T16: 549.42 | U16: 590.22 | V16: 629.38 | W16: 719.64 | X16: 763.88 | Y16: 781.77 | Z16: 974.59 | AA16: 747.47 | AB16: 818.88 | AC16: 923.91 | AD16: 995.14 | AE16: 1037.78
A17: Ireland | B17: 1565.12 | C17: 1811.88 | D17: 2150.62 | E17: 2360.89 | F17: 2705.73 | G17: 2976.16 | H17: 2779.55 | I17: 3091.19 | J17: 3300.24 | K17: 3835.4 | L17: 4219.42 | M17: 4470.1 | N17: 4822.63 | O17: 4314.14 | P17: 3847.45 | Q17: 4103.67 | R17: 4208.47 | S17: 4173.44 | T17: 4444.87 | U17: 4683.91 | V17: 4977.25 | W17: 5117.49 | X17: 5232.37 | Y17: 5119.3 | Z17: 5044.97 | AA17: 4505.41 | AB17: 4984.03 | AC17: 4427.9 | AD17: 4931.8 | AE17: 5501.53
A18: Greece | B18: 3291.79 | C18: 3662.37 | D18: 3740.65 | E18: 3635.91 | F18: 3588.88 | G18: 3190.58 | H18: 3360 | I18: 3713 | J18: 3856 | K18: 4116 | L18: 4208 | M18: 4433 | N18: 4837 | O18: 4972 | P18: 4944 | Q18: 5978 | R18: 6017 | S18: 6938 | T18: 7240 | U18: 7270 | V18: 7401 | W18: 7281 | X18: 7759 | Y18: 7402 | Z18: 7696 | AA18: 6818 | AB18: 7701 | AC18: 11635 | AD18: 9257 | AE18: 8910
A19: Spain | B19: 9976.01 | C19: 10648.87 | D19: 10655.98 | E19: 12242.27 | F19: 13412 | G19: 13791 | H19: 14159 | I19: 15091 | J19: 16025 | K19: 16810 | L19: 17620 | M19: 18371 | N19: 19076 | O19: 18179 | P19: 17335 | Q19: 17672 | R19: 16866 | S19: 16325 | T19: 19611 | U19: 19374 | V19: 20868 | W19: 20840 | X19: 21434 | Y19: 22158 | Z19: 22117 | AA19: 19697 | AB19: 21310 | AC19: 20665 | AD19: 22993 | AE19: 25643
A20: France | B20: 30596.99 | C20: 32258.39 | D20: 31325.75 | E20: 32738.17 | F20: 33117 | G20: 31919 | H20: 30032 | I20: 32496 | J20: 32115 | K20: 35229 | L20: 35221 | M20: 35950 | N20: 36205 | O20: 36455 | P20: 35894 | Q20: 37279 | R20: 39144 | S20: 40444 | T20: 42404 | U20: 43225 | V20: 47101 | W20: 49803 | X20: 52775 | Y20: 55740 | Z20: 56162 | AA20: 49304 | AB20: 54099 | AC20: 53798 | AD20: 51251 | AE20: 54315
A21: Croatia | B21: 551.21 | C21: 591.23 | D21: 576.05 | E21: 653.85 | F21: 660.94 | G21: 799.81 | H21: 910.87 | I21: 1158.92 | J21: 1266.66 | K21: 1334.76 | L21: 1396.68 | M21: 1610.08 | N21: 1785.43 | O21: 1823.36 | P21: 1694.91 | Q21: 1751.65 | R21: 1557.14 | S21: 1453.06 | T21: 1583.17 | U21: 1746.44 | V21: 1910.08 | W21: 2043.64 | X21: 2146.73 | Y21: 2295.46 | Z21: 2366.11 | AA21: 2057.66 | AB21: 2257.57 | AC21: 2298.02 | AD21: 2612.86 | AE21: 2885.56
... A37: Sweden | B37: 5292.38 | C37: 6691.37 | D37: 6565.79 | E37: 6770.6 | F37: 6900.26 | G37: 7414.27 | H37: 7081.39 | I37: 7617.75 | J37: 8124.22 | K37: 8404.48 | L37: 8711.62 | M37: 8958.23 | N37: 9167.68 | O37: 9364.76 | P37: 8667.12 | Q37: 9977.14 | R37: 10056.48 | S37: 10310.66 | T37: 10257.99 | U37: 9557.95 | V37: 9797.19 | W37: 10358.65 | X37: 10158.9 | Y37: 9816.93 | Z37: 9779.11 | AA37: 9597.99 | AB37: 10243.83 | AC37: 10651.29 | AD37: 10857.84 | AE37: 8938.64

Sheet energy tax mil euro
A1: Data extracted on 30/04/2026 21:21:12 from [ESTAT]
A2: Dataset: | B2: Environmental tax revenues [env_ac_tax__custom_21261132]
A3: Last updated: | B3: 10/02/2026 23:00
A5: Time frequency | B5: Annual
A6: Taxes | B6: Energy taxes
A7: Unit of measure | B7: Million euro
A9: TIME | B9: 1995 | C9: 1996 | D9: 1997 | E9: 1998 | F9: 1999 | G9: 2000 | H9: 2001 | I9: 2002 | J9: 2003 | K9: 2004 | L9: 2005 | M9: 2006 | N9: 2007 | O9: 2008 | P9: 2009 | Q9: 2010 | R9: 2011 | S9: 2012 | T9: 2013 | U9: 2014 | V9: 2015 | W9: 2016 | X9: 2017 | Y9: 2018 | Z9: 2019 | AA9: 2020 | AB9: 2021 | AC9: 2022 | AD9: 2023 | AE9: 2024
A10: European Union - 27 countries (from 2020) | B10: 125460.37 | C10: 133532.25 | D10: 136364.49 | E10: 141230.67 | F10: 151985.16 | G10: 155650.56 | H10: 162998.33 | I10: 170923.49 | J10: 180099.47 | K10: 184681.44 | L10: 188986.44 | M10: 194453.42 | N10: 197567.79 | O10: 201367.58 | P10: 206590.77 | Q10: 212157.89 | R10: 227806.28 | S10: 234301.7 | T10: 247292.51 | U10: 257557.55 | V10: 262044.77 | W10: 272119.18 | X10: 278140.98 | Y10: 282403.91 | Z10: 288633.81 | AA10: 265868.48 | AB10: 282537.17 | AC10: 268436.69 | AD10: 278660.35 | AE10: 294440.12
A11: Belgium | B11: 3303.63 | C11: 3450.06 | D11: 3474.55 | E11: 3556.54 | F11: 3598.7 | G11: 3613.9 | H11: 3632.2 | I11: 3673.6 | J11: 3960.8 | K11: 4458.4 | L11: 4698.2 | M11: 4656 | N11: 4939.6 | O11: 5035.2 | P11: 5064.9 | Q11: 5627.8 | R11: 6168.7 | S11: 6315 | T11: 6481.8 | U11: 6859.2 | V11: 7238.8 | W11: 8093.8 | X11: 8534 | Y11: 8779.2 | Z11: 8943.3 | AA11: 7972.9 | AB11: 8874.1 | AC11: 8691.4 | AD11: 9921.5 | AE11: 9723.9
A12: Bulgaria | B12: 157.7 | C12: 70.68 | D12: 114.17 | E12: 299.59 | F12: 293.7 | G12: 377.23 | H12: 370.46 | I12: 365.86 | J12: 459.96 | K12: 553.71 | L12: 628.77 | M12: 659.8 | N12: 921.16 | O12: 1059.93 | P12: 933.58 | Q12: 926.78 | R12: 982.74 | S12: 995.13 | T12: 1054.59 | U12: 1068.64 | V12: 1192.26 | W12: 1267.36 | X12: 1281.25 | Y12: 1264.25 | Z12: 1626.93 | AA12: 1642.06 | AB12: 1743.95 | AC12: 3858.41 | AD12: 2924.81 | AE12: 2835.03
A13: Czechia | B13: 976.57 | C13: 1062.22 | D13: 1069 | E13: 1125.75 | F13: 1235.71 | G13: 1320.21 | H13: 1569.45 | I13: 1758.64 | J13: 1851.47 | K13: 2131.45 | L13: 2495.27 | M13: 2712.65 | N13: 2939.03 | O13: 3363.59 | P13: 3182.07 | Q13: 3314.98 | R13: 3574.58 | S13: 3349.04 | T13: 3106.81 | U13: 3103.17 | V13: 3217.57 | W13: 3465.15 | X13: 3621.55 | Y13: 3841.35 | Z13: 4301.44 | AA13: 3880.7 | AB13: 4119.89 | AC13: 3992.79 | AD13: 4869.02 | AE13: 4553.82
A14: Denmark | B14: 2952.88 | C14: 3287.43 | D14: 3308.19 | E14: 4203.13 | F14: 4700.54 | G14: 4853.52 | H14: 5252.64 | I14: 5429.63 | J14: 5429.37 | K14: 5594.15 | L14: 5360.09 | M14: 5060.74 | N14: 5464.16 | O14: 5166.74 | P14: 5361.41 | Q14: 5744.83 | R14: 5958.8 | S14: 6076.99 | T14: 6214.35 | U14: 6197.19 | V14: 6022.87 | W14: 6151.2 | X14: 5861.37 | Y14: 5775.84 | Z14: 5308.49 | AA14: 5165.73 | AB14: 5219.66 | AC14: 4952.77 | AD14: 4051.54 | AE14: 5009.21
A15: Germany | B15: 34720.1 | C15: 35134.54 | D15: 34171.68 | E15: 34099.15 | F15: 39297 | G15: 43953 | H15: 47832 | I15: 49597 | J15: 53889 | K15: 53109 | L15: 52157 | M15: 53593 | N15: 53862 | O15: 55300 | P15: 58181 | Q15: 55358 | R15: 62804 | S15: 63224 | T15: 68765 | U15: 72286 | V15: 71004 | W15: 72436 | X15: 75195 | Y15: 74310 | Z15: 75185 | AA15: 72982 | AB15: 71915 | AC15: 62510 | AD15: 59767 | AE15: 64249
A16: Estonia | B16: 16.2 | C16: 38.84 | D16: 53.23 | E16: 79.75 | F16: 72.52 | G16: 76.06 | H16: 111.39 | I16: 116.69 | J16: 133.9 | K16: 173.76 | L16: 215.88 | M16: 243.11 | N16: 297.99 | O16: 334.55 | P16: 383.91 | Q16: 432.84 | R16: 442.03 | S16: 503.79 | T16: 485.72 | U16: 520.93 | V16: 557.78 | W16: 641.73 | X16: 682.41 | Y16: 696.55 | Z16: 902.1 | AA16: 691.73 | AB16: 757.51 | AC16: 851.84 | AD16: 930.78 | AE16: 973.78
A17: Ireland | B17: 887.67 | C17: 1001.31 | D17: 1197.85 | E17: 1307.98 | F17: 1434.51 | G17: 1491.34 | H17: 1435.77 | I17: 1674.01 | J17: 1762.91 | K17: 2084.22 | L17: 2212.29 | M17: 2232.49 | N17: 2250.47 | O17: 2249.81 | P17: 2267.87 | Q17: 2520.3 | R17: 2696.32 | S17: 2634.41 | T17: 2721.34 | U17: 2840.2 | V17: 3042.88 | W17: 3135.25 | X17: 3258 | Y17: 3176.04 | Z17: 3039.54 | AA17: 2786.16 | AB17: 3233.49 | AC17: 2647.76 | AD17: 3030.2 | AE17: 3472.25
A18: Greece | B18: 2462.94 | C18: 2688.79 | D18: 2700.84 | E18: 2450.04 | F18: 2327.38 | G18: 2040.67 | H18: 2142 | I18: 2233 | J18: 2382 | K18: 2424 | L18: 2512 | M18: 2643 | N18: 2895 | O18: 3042 | P18: 3129 | Q18: 4454 | R18: 4584 | S18: 5622 | T18: 5965 | U18: 5961 | V18: 6030 | W18: 5891 | X18: 6319 | Y18: 5929 | Z18: 6186 | AA18: 5418 | AB18: 6213 | AC18: 9989 | AD18: 7547 | AE18: 7227
A19: Spain | B19: 8139.64 | C19: 8725.7 | D19: 8739.23 | E19: 9921.4 | F19: 10699 | G19: 10936 | H19: 11168 | I19: 12018 | J19: 12721 | K19: 13253 | L19: 13627 | M19: 14051 | N19: 14581 | O19: 14452 | P19: 14070 | Q19: 14423 | R19: 13794 | S19: 13277 | T19: 16124 | U19: 16104 | V19: 17400 | W19: 17207 | X19: 17698 | Y19: 18257 | Z19: 18086 | AA19: 16020 | AB19: 17323 | AC19: 16562 | AD19: 17726 | AE19: 20129
A20: France | B20: 23804.25 | C20: 24795.65 | D20: 24864.98 | E20: 25979.29 | F20: 26605 | G20: 26300 | H20: 25210 | I20: 27427 | J20: 27365 | K20: 28593 | L20: 28327 | M20: 28710 | N20: 28414 | O20: 28177 | P20: 28078 | Q20: 29583 | R20: 30808 | S20: 31600 | T20: 33607 | U20: 34342 | V20: 38360 | W20: 41194 | X20: 43862 | Y20: 46599 | Z20: 47012 | AA20: 41090 | AB20: 45300 | AC20: 44498 | AD20: 41197 | AE20: 43591
A21: Croatia | B21: 378.63 | C21: 395.67 | D21: 392.15 | E21: 443.92 | F21: 453.18 | G21: 606.31 | H21: 645.5 | I21: 757.86 | J21: 790.37 | K21: 801.31 | L21: 823.37 | M21: 866.71 | N21: 889.86 | O21: 855.37 | P21: 885.75 | Q21: 984.54 | R21: 818.02 | S21: 768.3 | T21: 895.11 | U21: 1003.82 | V21: 1126.25 | W21: 1220.49 | X21: 1267.31 | Y21: 1407.14 | Z21: 1468.37 | AA21: 1264.46 | AB21: 1418.51 | AC21: 1409.75 | AD21: 1627.71 | AE21: 1832.34
... A37: Sweden | B37: 4517.62 | C37: 5692.51 | D37: 5626.39 | E37: 5820.16 | F37: 5887.71 | G37: 6194.64 | H37: 5980.92 | I37: 6449.12 | J37: 6924.99 | K37: 7173.48 | L37: 7290.19 | M37: 7445.86 | N37: 7519.49 | O37: 7516.64 | P37: 6996.73 | Q37: 8121.17 | R37: 8171.5 | S37: 8384.67 | T37: 8231.29 | U37: 7590.48 | V37: 7664.62 | W37: 8150.79 | X37: 7898.31 | Y37: 7511.19 | Z37: 7408.09 | AA37: 7206.53 | AB37: 7644.02 | AC37: 8100.21 | AD37: 8515.52 | AE37: 6565.58

Sheet transport tax mil euro
A1: Data extracted on 30/04/2026 21:21:12 from [ESTAT]
A2: Dataset: | B2: Environmental tax revenues [env_ac_tax__custom_21261132]
A3: Last updated: | C3: 10/02/2026 23:00
A5: Time frequency | C5: Annual
A6: Taxes | C6: Transport taxes
A7: Unit of measure | C7: Million euro
A9: TIME | B9: 1995 | C9: 1996 | D9: 1997 | E9: 1998 | F9: 1999 | G9: 2000 | H9: 2001 | I9: 2002 | J9: 2003 | K9: 2004 | L9: 2005 | M9: 2006 | N9: 2007 | O9: 2008 | P9: 2009 | Q9: 2010 | R9: 2011 | S9: 2012 | T9: 2013 | U9: 2014 | V9: 2015 | W9: 2016 | X9: 2017 | Y9: 2018 | Z9: 2019 | AA9: 2020 | AB9: 2021 | AC9: 2022 | AD9: 2023 | AE9: 2024
A10: European Union - 27 countries (from 2020) | B10: 32875.16 | C10: 35560.1 | D10: 35500.09 | E10: 38551.66 | F10: 40777.45 | G10: 40545.64 | H10: 41773.76 | I10: 42467.79 | J10: 43338.55 | K10: 48532.6 | L10: 52051.46 | M10: 54882.11 | N10: 57788.3 | O10: 56292.98 | P10: 50928.11 | Q10: 52042.35 | R10: 53651.01 | S10: 53417.09 | T10: 53622.38 | U10: 54667.83 | V10: 56630.45 | W10: 58457.18 | X10: 60004.98 | Y10: 61993.7 | Z10: 63002.5 | AA10: 57573.57 | AB10: 58967.74 | AC10: 59761.82 | AD10: 62787.77 | AE10: 65543.65
A11: Belgium | B11: 1654.01 | C11: 1940.9 | D11: 1942.39 | E11: 1916.26 | F11: 2160.1 | G11: 2068.3 | H11: 2222.7 | I11: 2274.8 | J11: 2359.7 | K11: 2410.6 | L11: 2529 | M11: 2479.4 | N11: 2584.7 | O11: 2536.5 | P11: 2618.2 | Q11: 2662.3 | R11: 2888.4 | S11: 2799.1 | T11: 2843 | U11: 2795.8 | V11: 2858 | W11: 2826.1 | X11: 2918.8 | Y11: 3018 | Z11: 3092.3 | AA11: 3043.9 | AB11: 3107.2 | AC11: 3116.5 | AD11: 3352.5 | AE11: 3406.4
A12: Bulgaria | B12: 16.15 | C12: 8.73 | D12: 1.7 | E12: 13.76 | F12: 20.36 | G12: 23.55 | H12: 23.44 | I12: 30.75 | J12: 40.07 | K12: 42.46 | L12: 49.61 | M12: 71.12 | N12: 89.63 | O12: 114.41 | P12: 101.18 | Q12: 95.87 | R12: 90.06 | S12: 103.21 | T12: 114.51 | U12: 121.41 | V12: 128.84 | W12: 151.11 | X12: 156.75 | Y12: 174.26 | Z12: 180.57 | AA12: 190.46 | AB12: 207.66 | AC12: 210.69 | AD12: 220.31 | AE12: 232.92
A13: Czechia | B13: 141.86 | C13: 156.89 | D13: 110.33 | E13: 125.19 | F13: 149.66 | G13: 156.18 | H13: 160.06 | I13: 184.81 | J13: 182.63 | K13: 174.85 | L13: 183 | M13: 209.79 | N13: 226.25 | O13: 248.26 | P13: 198.68 | Q13: 214.68 | R13: 226.11 | S13: 219.33 | T13: 216.05 | U13: 214.52 | V13: 228.78 | W13: 237.26 | X13: 253.06 | Y13: 262.76 | Z13: 269.38 | AA13: 237.5 | AB13: 226.91 | AC13: 58.21 | AD13: 57.7 | AE13: 62.58
A14: Denmark | B14: 2841.84 | C14: 2994.51 | D14: 3159.6 | E14: 3483.42 | F14: 3446.68 | G14: 3129.76 | H14: 2998.75 | I14: 3418.72 | J14: 3242.18 | K14: 3876.1 | L14: 4484.39 | M14: 4856.12 | N14: 4934.8 | O14: 4243.29 | P14: 3274.54 | Q14: 3520.2 | R14: 3487.6 | S14: 3430.85 | T14: 3810.99 | U14: 3885.42 | V14: 4198.9 | W14: 4375.13 | X14: 4420.28 | Y14: 4514.01 | Z14: 4441.1 | AA14: 4208.04 | AB14: 3934.5 | AC14: 3278.25 | AD14: 3157.3 | AE14: 2654.99
A15: Germany | B15: 7358.83 | C15: 7190.17 | D15: 7327.98 | E15: 7697.66 | F15: 7040 | G15: 7010 | H15: 8380 | I15: 7600 | J15: 7340 | K15: 7740 | L15: 8680 | M15: 8940 | N15: 8910 | O15: 8840 | P15: 8200 | Q15: 8487 | R15: 9381 | S15: 9397 | T15: 9445 | U15: 9490 | V15: 9833 | W15: 10027 | X15: 10065 | Y15: 10249 | Z15: 10538 | AA15: 9876 | AB15: 10086 | AC15: 10667 | AD15: 11024 | AE15: 11545
A16: Estonia | B16: 5.61 | C16: 9.09 | D16: 8.35 | E16: 8.47 | F16: 10.32 | G16: 13.05 | H16: 14.59 | I16: 15.42 | J16: 3.8 | K16: 7.11 | L16: 7.91 | M16: 9.31 | N16: 9.49 | O16: 7.47 | P16: 6.42 | Q16: 7.45 | R16: 9.84 | S16: 10.79 | T16: 10.94 | U16: 11.31 | V16: 12.16 | W16: 12.53 | X16: 13.05 | Y16: 13.24 | Z16: 13.37 | AA16: 11.1 | AB16: 12.67 | AC16: 12.73 | AD16: 12.21 | AE16: 12.42
A17: Ireland | B17: 677.45 | C17: 810.57 | D17: 952.77 | E17: 1052.91 | F17: 1271.21 | G17: 1483.68 | H17: 1342.62 | I17: 1387.64 | J17: 1493.96 | K17: 1708.05 | L17: 1960.78 | M17: 2185.86 | N17: 2515.76 | O17: 2002.52 | P17: 1522.71 | Q17: 1522.04 | R17: 1448.82 | S17: 1472.09 | T17: 1664.16 | U17: 1796.15 | V17: 1887.14 | W17: 1923.95 | X17: 1928.81 | Y17: 1917.11 | Z17: 1986.75 | AA17: 1708.16 | AB17: 1737.18 | AC17: 1761.67 | AD17: 1892.2 | AE17: 1999.6
A18: Greece | B18: 828.85 | C18: 973.58 | D18: 1039.8 | E18: 1185.87 | F18: 1261.49 | G18: 1149.9 | H18: 1218 | I18: 1480 | J18: 1474 | K18: 1692 | L18: 1696 | M18: 1790 | N18: 1942 | O18: 1930 | P18: 1815 | Q18: 1524 | R18: 1433 | S18: 1316 | T18: 1275 | U18: 1309 | V18: 1371 | W18: 1390 | X18: 1440 | Y18: 1455 | Z18: 1501 | AA18: 1396 | AB18: 1475 | AC18: 1573 | AD18: 1681 | AE18: 1653
A19: Spain | B19: 1807.79 | C19: 1885.91 | D19: 1874.63 | E19: 2222.34 | F19: 2593 | G19: 2732 | H19: 2859 | I19: 2922 | J19: 3113 | K19: 3380 | L19: 3818 | M19: 4123 | N19: 4286 | O19: 3490 | P19: 3074 | Q19: 3003 | R19: 2813 | S19: 2686 | T19: 2676 | U19: 2549 | V19: 2553 | W19: 2666 | X19: 2726 | Y19: 2865 | Z19: 2963 | AA19: 2631 | AB19: 2821 | AC19: 3026 | AD19: 3109 | AE19: 3223
A20: France | B20: 5028.46 | C20: 5491.73 | D20: 4888.48 | E20: 5146.17 | F20: 4779 | G20: 3605 | H20: 2666 | I20: 2697 | J20: 2557 | K20: 4506 | L20: 4771 | M20: 5044 | N20: 5379 | O20: 5808 | P20: 5512 | Q20: 5414 | R20: 5754 | S20: 5983 | T20: 5859 | U20: 5893 | V20: 5873 | W20: 5716 | X20: 5996 | Y20: 6394 | Z20: 6402 | AA20: 5537 | AB20: 5709 | AC20: 6026 | AD20: 6459 | AE20: 7472
A21: Croatia | B21: 25.2 | C21: 42.26 | D21: 33.17 | E21: 49.12 | F21: 52.31 | G21: 49.05 | H21: 104.93 | I21: 238.71 | J21: 305.07 | K21: 350.38 | L21: 393.06 | M21: 437.97 | N21: 475.96 | O21: 511.61 | P21: 389.04 | Q21: 385.91 | R21: 382.04 | S21: 356.31 | T21: 354.96 | U21: 376.33 | V21: 379.41 | W21: 401.57 | X21: 443.01 | Y21: 428.04 | Z21: 442.22 | AA21: 371.68 | AB21: 387.05 | AC21: 413.24 | AD21: 479.93 | AE21: 530.86
... A37: Sweden | B37: 644.03 | C37: 819.88 | D37: 784.75 | E37: 795.21 | F37: 853.93 | G37: 930.59 | H37: 849.69 | I37: 916.81 | J37: 942.11 | K37: 992.73 | L37: 1211.14 | M37: 1296.46 | N37: 1435.44 | O37: 1668.82 | P37: 1542.32 | Q37: 1719.56 | R37: 1741.01 | S37: 1792.49 | T37: 1907.41 | U37: 1846.9 | V37: 2004.92 | W37: 2080.28 | X37: 2067.86 | Y37: 2057.16 | Z37: 2118.78 | AA37: 2105.43 | AB37: 2268.27 | AC37: 2224.64 | AD37: 2053.09 | AE37: 2041.55

Sheet pol tax mil euro
A1: Data extracted on 30/04/2026 21:21:12 from [ESTAT]
A2: Dataset: | B2: Environmental tax revenues [env_ac_tax__custom_21261132]
A3: Last updated: | B3: 10/02/2026 23:00
A5: Time frequency | B5: Annual
A6: Taxes | B6: Taxes on pollution/resources
A7: Unit of measure | B7: Million euro
A9: TIME | B9: 1995 | C9: 1996 | D9: 1997 | E9: 1998 | F9: 1999 | G9: 2000 | H9: 2001 | I9: 2002 | J9: 2003 | K9: 2004 | L9: 2005 | M9: 2006 | N9: 2007 | O9: 2008 | P9: 2009 | Q9: 2010 | R9: 2011 | S9: 2012 | T9: 2013 | U9: 2014 | V9: 2015 | W9: 2016 | X9: 2017 | Y9: 2018 | Z9: 2019 | AA9: 2020 | AB9: 2021 | AC9: 2022 | AD9: 2023 | AE9: 2024
A10: European Union - 27 countries (from 2020) | B10: 5301.99 | C10: 6068.84 | D10: 5948.61 | E10: 6443.49 | F10: 6468.29 | G10: 7270.12 | H10: 7447.74 | I10: 7957.65 | J10: 7850.3 | K10: 7950.88 | L10: 8012.94 | M10: 8673.11 | N10: 9178.15 | O10: 9654.86 | P10: 9059.22 | Q10: 9154.82 | R10: 9533.66 | S10: 9881.35 | T10: 10038.98 | U10: 10476.3 | V10: 10885.35 | W10: 10978.5 | X10: 11140.75 | Y10: 11186.9 | Z10: 11409.47 | AA10: 11453.94 | AB10: 12144.96 | AC10: 12632.15 | AD10: 14548.66 | AE10: 14773.1
A11: Belgium | B11: 346.35 | C11: 460.08 | D11: 528.37 | E11: 512.73 | F11: 525 | G11: 484.8 | H11: 465.7 | I11: 453.2 | J11: 475.7 | K11: 649.3 | L11: 628.5 | M11: 523.2 | N11: 498.9 | O11: 509.4 | P11: 505.4 | Q11: 531.6 | R11: 515.8 | S11: 512.5 | T11: 519.1 | U11: 509.9 | V11: 497.3 | W11: 560.3 | X11: 540.8 | Y11: 583.9 | Z11: 574.1 | AA11: 585.8 | AB11: 547.6 | AC11: 582.8 | AD11: 608.1 | AE11: 593.5
A12: Bulgaria | B12: 0.65 | C12: 0.63 | D12: 0.17 | E12: 0.53 | F12: 0.8 | G12: 0.76 | H12: 0.95 | I12: 16.41 | J12: 26.86 | K12: 37.3 | L12: 34.1 | M12: 31.74 | N12: 25.25 | O12: 47.38 | P12: 27.96 | Q12: 28.95 | R12: 34.98 | S12: 20.21 | T12: 31.83 | U12: 30.62 | V12: 30.63 | W12: 32.68 | X12: 30.89 | Y12: 31.94 | Z12: 31.62 | AA12: 26.57 | AB12: 27.05 | AC12: 25.99 | AD12: 31.09 | AE12: 29.8
A13: Czechia | B13: 87.01 | C13: 78.21 | D13: 72.84 | E13: 48.21 | F13: 41.37 | G13: 35.03 | H13: 32.49 | I13: 36.36 | J13: 34.51 | K13: 29.13 | L13: 30.15 | M13: 27.77 | N13: 33.42 | O13: 31.95 | P13: 46.83 | Q13: 47.78 | R13: 45.38 | S13: 38.05 | T13: 28.48 | U13: 29.27 | V13: 30.98 | W13: 25.97 | X13: 22.37 | Y13: 25.03 | Z13: 24.04 | AA13: 29.86 | AB13: 26.64 | AC13: 25.52 | AD13: 30.41 | AE13: 24.84
A14: Denmark | B14: 304.71 | C14: 427.16 | D14: 527.1 | E14: 634.94 | F14: 673.78 | G14: 621.66 | H14: 614.32 | I14: 639.85 | J14: 622.62 | K14: 627.09 | L14: 630.3 | M14: 649.06 | N14: 683.1 | O14: 667.72 | P14: 599.19 | Q14: 503.44 | R14: 510.19 | S14: 587.79 | T14: 657.93 | U14: 569.15 | V14: 624.73 | W14: 555.7 | X14: 508.68 | Y14: 525.37 | Z14: 497.01 | AA14: 517.51 | AB14: 549.46 | AC14: 540.38 | AD14: 525.96 | AE14: 546.56
A15: Germany | B15: 0 | C15: 0 | D15: 0 | E15: 0 | F15: 0 | G15: 0 | H15: 0 | I15: 0 | J15: 0 | K15: 0 | L15: 0 | M15: 0 | N15: 0 | O15: 0 | P15: 0 | Q15: 0 | R15: 0 | S15: 0 | T15: 0 | U15: 0 | V15: 0 | W15: 0 | X15: 0 | Y15: 0 | Z15: 0 | AA15: 0 | AB15: 0 | AC15: 0 | AD15: 0 | AE15: 0
A16: Estonia | B16: 3.81 | C16: 4.74 | D16: 6.59 | E16: 7.18 | F16: 7.83 | G16: 15.28 | H16: 21.37 | I16: 22.48 | J16: 26.83 | K16: 23 | L16: 31.93 | M16: 43.53 | N16: 54.57 | O16: 54.73 | P16: 53.54 | Q16: 45.2 | R16: 48.68 | S16: 46.36 | T16: 52.76 | U16: 57.98 | V16: 59.44 | W16: 65.38 | X16: 68.42 | Y16: 71.98 | Z16: 59.12 | AA16: 44.64 | AB16: 48.7 | AC16: 59.34 | AD16: 52.15 | AE16: 51.58
A17: Ireland | B17: 0 | C17: 0 | D17: 0 | E17: 0 | F17: 0 | G17: 1.14 | H17: 1.16 | I17: 29.54 | J17: 43.37 | K17: 43.13 | L17: 46.34 | M17: 51.75 | N17: 56.4 | O17: 61.82 | P17: 56.87 | Q17: 61.33 | R17: 63.33 | S17: 66.95 | T17: 59.37 | U17: 47.57 | V17: 47.22 | W17: 58.28 | X17: 45.56 | Y17: 26.16 | Z17: 18.68 | AA17: 11.09 | AB17: 13.36 | AC17: 18.47 | AD17: 9.39 | AE17: 29.68
A18: Greece | B18: 0 | C18: 0 | D18: 0 | E18: 0 | F18: 0 | G18: 0 | H18: 0 | I18: 0 | J18: 0 | K18: 0 | L18: 0 | M18: 0 | N18: 0 | O18: 0 | P18: 0 | Q18: 0 | R18: 0 | S18: 0 | T18: 0 | U18: 0 | V18: 0 | W18: 0 | X18: 0 | Y18: 18 | Z18: 9 | AA18: 4 | AB18: 13 | AC18: 73 | AD18: 29 | AE18: 30
A19: Spain | B19: 28.58 | C19: 37.26 | D19: 42.13 | E19: 98.53 | F19: 120 | G19: 123 | H19: 132 | I19: 151 | J19: 191 | K19: 177 | L19: 175 | M19: 197 | N19: 209 | O19: 237 | P19: 191 | Q19: 246 | R19: 259 | S19: 362 | T19: 811 | U19: 721 | V19: 915 | W19: 967 | X19: 1010 | Y19: 1036 | Z19: 1068 | AA19: 1046 | AB19: 1166 | AC19: 1077 | AD19: 2158 | AE19: 2291
A20: France | B20: 1764.28 | C20: 1971 | D20: 1572.29 | E20: 1612.71 | F20: 1733 | G20: 2014 | H20: 2156 | I20: 2372 | J20: 2193 | K20: 2130 | L20: 2123 | M20: 2196 | N20: 2412 | O20: 2470 | P20: 2304 | Q20: 2282 | R20: 2582 | S20: 2861 | T20: 2938 | U20: 2990 | V20: 2868 | W20: 2893 | X20: 2917 | Y20: 2747 | Z20: 2748 | AA20: 2677 | AB20: 3090 | AC20: 3274 | AD20: 3595 | AE20: 3252
A21: Croatia | B21: 147.38 | C21: 153.3 | D21: 150.73 | E21: 160.81 | F21: 155.46 | G21: 144.46 | H21: 160.44 | I21: 162.34 | J21: 171.22 | K21: 183.07 | L21: 180.24 | M21: 305.4 | N21: 419.61 | O21: 456.39 | P21: 420.11 | Q21: 381.19 | R21: 357.07 | S21: 328.45 | T21: 333.11 | U21: 366.29 | V21: 404.42 | W21: 421.57 | X21: 436.41 | Y21: 460.27 | Z21: 455.53 | AA21: 421.53 | AB21: 452 | AC21: 475.03 | AD21: 505.22 | AE21: 522.36
... A37: Sweden | B37: 130.73 | C37: 178.98 | D37: 154.66 | E37: 155.23 | F37: 158.61 | G37: 289.04 | H37: 250.78 | I37: 251.83 | J37: 257.12 | K37: 238.26 | L37: 210.29 | M37: 215.9 | N37: 212.75 | O37: 179.3 | P37: 128.07 | Q37: 136.41 | R37: 143.97 | S37: 133.5 | T37: 119.29 | U37: 120.57 | V37: 127.65 | W37: 127.58 | X37: 192.73 | Y37: 248.58 | Z37: 252.24 | AA37: 286.03 | AB37: 331.54 | AC37: 326.45 | AD37: 289.23 | AE37: 331.51

Sheet POPULATION
A1: Data extracted on 30/04/2026 21:18:31 from [ESTAT] | B1: Population on 1 January by age and sex [demo_pjan__custom_21261123]
A2: Dataset: | B2: 09/04/2026 23:00
A3: Last updated:
A5: Time frequency | B5: Annual
A6: Unit of measure | B6: Number
A7: Age class | B7: Total
A8: Sex | B8: Total
A10: TIME | B10: 1995 | C10: 1996 | D10: 1997 | E10: 1998 | F10: 1999 | G10: 2000 | H10: 2001 | I10: 2002 | J10: 2003 | K10: 2004 | L10: 2005 | M10: 2006 | N10: 2007 | O10: 2008 | P10: 2009 | Q10: 2010 | R10: 2011 | S10: 2012 | T10: 2013 | U10: 2014 | V10: 2015 | W10: 2016 | X10: 2017 | Y10: 2018 | Z10: 2019 | AA10: 2020 | AB10: 2021 | AC10: 2022 | AD10: 2023 | AE10: 2024
A11: European Union - 27 countries (from 2020) | B11: 423960534 | C11: 424641798 | D11: 425273491 | E11: 427482962 | F11: 427998269 | G11: 428473834 | H11: 429240746 | I11: 429723142 | J11: 431190184 | K11: 432762039 | L11: 434416272 | M11: 435816236 | N11: 437227496 | O11: 438725386 | P11: 440047892 | Q11: 440660421 | R11: 439942305 | S11: 440552661 | T11: 441739930 | U11: 442268078 | V11: 442924865 | W11: 444003268 | X11: 444670605 | Y11: 445301376 | Z11: 446149924 | AA11: 447030024 | AB11: 445891011 | AC11: 445972024 | AD11: 447695350 | AE11: 449306184
A12: Belgium | B12: 10130574 | C12: 10143047 | D12: 10170226 | E12: 10192264 | F12: 10213752 | G12: 10239085 | H12: 10263414 | I12: 10309725 | J12: 10355844 | K12: 10396421 | L12: 10445852 | M12: 10511382 | N12: 10584534 | O12: 10666866 | P12: 10753080 | Q12: 10839905 | R12: 11000638 | S12: 11075889 | T12: 11137974 | U12: 11180840 | V12: 11237274 | W12: 11311117 | X12: 11351727 | Y12: 11398589 | Z12: 11455519 | AA12: 11522440 | AB12: 11554767 | AC12: 11617623 | AD12: 11742796 | AE12: 11817096
A13: Bulgaria | B13: 8427418 | C13: 8384715 | D13: 8340936 | E13: 8283200 | F13: 8230371 | G13: 8190876 | H13: 8149468 | I13: 7868815 | J13: 7805506 | K13: 7745147 | L13: 7688573 | M13: 7629371 | N13: 7572673 | O13: 7518002 | P13: 7467119 | Q13: 7421766 | R13: 7369431 | S13: 7327224 | T13: 7202556 | U13: 7117453 | V13: 7029690 | W13: 6938759 | X13: 6849518 | Y13: 6757418 | Z13: 6664177 | AA13: 6569275 | AB13: 6532117 | AC13: 6482484 | AD13: 6447710 | AE13: 6445481
A14: Czechia | B14: 10333161 | C14: 10321344 | D14: 10309137 | E14: 10299125 | F14: 10289621 | G14: 10278098 | H14: 10232027 | I14: 10201182 | J14: 10192649 | K14: 10195347 | L14: 10198855 | M14: 10223577 | N14: 10254233 | O14: 10343422 | P14: 10425783 | Q14: 10462088 | R14: 10486731 | S14: 10505445 | T14: 10516125 | U14: 10512419 | V14: 10538275 | W14: 10553843 | X14: 10578820 | Y14: 10610055 | Z14: 10649800 | AA14: 10693939 | AB14: 10494836 | AC14: 10516707 | AD14: 10827529 | AE14: 10900555
A15: Denmark | B15: 5215718 | C15: 5251027 | D15: 5275121 | E15: 5294860 | F15: 5313577 | G15: 5330020 | H15: 5349212 | I15: 5368354 | J15: 5383507 | K15: 5397640 | L15: 5411405 | M15: 5427459 | N15: 5447084 | O15: 5475791 | P15: 5511451 | Q15: 5534738 | R15: 5560628 | S15: 5580516 | T15: 5602628 | U15: 5627235 | V15: 5659715 | W15: 5707251 | X15: 5748769 | Y15: 5781190 | Z15: 5806081 | AA15: 5822763 | AB15: 5840045 | AC15: 5873420 | AD15: 5932654 | AE15: 5961249
A16: Germany | B16: 81538603 | C16: 81817499 | D16: 82012162 | E16: 82057379 | F16: 82037011 | G16: 82163475 | H16: 82259540 | I16: 82440309 | J16: 82536680 | K16: 82531671 | L16: 82500849 | M16: 82437995 | N16: 82314906 | O16: 82217837 | P16: 82002356 | Q16: 81802257 | R16: 80222065 | S16: 80327900 | T16: 80523746 | U16: 80767463 | V16: 81197537 | W16: 82175684 | X16: 82521653 | Y16: 82792351 | Z16: 83019213 | AA16: 83166711 | AB16: 83155031 | AC16: 83237124 | AD16: 83118501 | AE16: 83456045
A17: Estonia | B17: 1448075 | C17: 1425192 | D17: 1405996 | E17: 1393074 | F17: 1379237 | G17: 1401250 | H17: 1392720 | I17: 1383510 | J17: 1375190 | K17: 1366250 | L17: 1358850 | M17: 1350700 | N17: 1342920 | O17: 1338440 | P17: 1335740 | Q17: 1333290 | R17: 1329660 | S17: 1325217 | T17: 1320174 | U17: 1315819 | V17: 1314870 | W17: 1315944 | X17: 1315635 | Y17: 1319133 | Z17: 1324820 | AA17: 1328976 | AB17: 1330068 | AC17: 1331796 | AD17: 1365884 | AE17: 1374687
A18: Ireland | B18: 3597617 | C18: 3620065 | D18: 3654955 | E18: 3693386 | F18: 3732006 | G18: 3777565 | H18: 3832783 | I18: 3899702 | J18: 3964191 | K18: 4028851 | L18: 4111672 | M18: 4208156 | N18: 4340118 | O18: 4457765 | P18: 4521322 | Q18: 4549428 | R18: 4570881 | S18: 4589287 | T18: 4609779 | U18: 4637852 | V18: 4677627 | W18: 4726286 | X18: 4799157 | Y18: 4855733 | Z18: 4940311 | AA18: 5012600 | AB18: 5066893 | AC18: 5154277 | AD18: 5271395 | AE18: 5351681
A19: Greece | B19: 10535973 | C19: 10588332 | D19: 10629267 | E19: 10693250 | F19: 10747768 | G19: 10775627 | H19: 10835989 | I19: 10888274 | J19: 10915770 | K19: 10940369 | L19: 10969912 | M19: 11004716 | N19: 11036008 | O19: 11060937 | P19: 11094745 | Q19: 11119289 | R19: 11123392 | S19: 11072725 | T19: 10980006 | U19: 10894294 | V19: 10818041 | W19: 10735415 | X19: 10707527 | Y19: 10667336 | Z19: 10635213 | AA19: 10612591 | AB19: 10555344 | AC19: 10461627 | AD19: 10401868 | AE19: 10375764
A20: Spain | B20: 39639726 | C20: 39808374 | D20: 39971329 | E20: 40143449 | F20: 40303568 | G20: 40470182 | H20: 40665545 | I20: 41035278 | J20: 41827838 | K20: 42547451 | L20: 43296338 | M20: 44009971 | N20: 44784666 | O20: 45668939 | P20: 46239273 | Q20: 46486619 | R20: 46667174 | S20: 46818219 | T20: 46712650 | U20: 46495744 | V20: 46425722 | W20: 46418884 | X20: 46497393 | Y20: 46645070 | Z20: 46918951 | AA20: 47318050 | AB20: 47400798 | AC20: 47486843 | AD20: 48085361 | AE20: 48619695
A21: France | B21: 59315139 | C21: 59522297 | D21: 59726386 | E21: 59934884 | F21: 60158533 | G21: 60545022 | H21: 60979315 | I21: 61424036 | J21: 61864088 | K21: 62292241 | L21: 62772870 | M21: 63229635 | N21: 63645065 | O21: 64007193 | P21: 64350226 | Q21: 64658856 | R21: 64978721 | S21: 65276983 | T21: 65600350 | U21: 66165980 | V21: 66458153 | W21: 66638391 | X21: 66809816 | Y21: 67026224 | Z21: 67290471 | AA21: 67473651 | AB21: 67728568 | AC21: 68091703 | AD21: 68277210 | AE21: 68669303
A22: Croatia | B22: 4658893 | C22: 4581167 | D22: 4533028 | E22: 4536812 | F22: 4527460 | G22: 4497735 | H22: 4295406 | I22: 4305494 | J22: 4305384 | K22: 4305725 | L22: 4310861 | M22: 4312487 | N22: 4313530 | O22: 4311967 | P22: 4309796 | Q22: 4302847 | R22: 4289857 | S22: 4275984 | T22: 4247803 | U22: 4217632 | V22: 4180915 | W22: 4131115 | X22: 4078769 | Y22: 4014341 | Z22: 3968676 | AA22: 3933511 | AB22: 3893026 | AC22: 3862305 | AD22: 3850894 | AE22: 3861967
... A38: Sweden | B38: 8816381 | C38: 8837496 | D38: 8844499 | E38: 8847625 | F38: 8854322 | G38: 8861426 | H38: 8882792 | I38: 8909128 | J38: 8940788 | K38: 8975670 | L38: 9011392 | M38: 9047752 | N38: 9113257 | O38: 9182927 | P38: 9256347 | Q38: 9340682 | R38: 9415570 | S38: 9482855 | T38: 9555893 | U38: 9644864 | V38: 9747355 | W38: 9851017 | X38: 9995153 | Y38: 10120242 | Z38: 10230185 | AA38: 10327589 | AB38: 10379295 | AC38: 10452326 | AD38: 10521556 | AE38: 10551707

Sheet total tax euro pers
A1: Data extracted on 30/04/2026 21:21:12 from [ESTAT]
A2: Dataset: | C2: Environmental tax revenues [env_ac_tax__custom_21261132]
A3: Last updated: | C3: 10/02/2026 23:00
A5: Time frequency | C5: Annual
A6: Taxes | C6: Total environmental taxes
A7: Unit of measure | C7: euro/pers
A9: TIME | B9: 1995 | C9: 1996 | D9: 1997 | E9: 1998 | F9: 1999 | G9: 2000 | H9: 2001 | I9: 2002 | J9: 2003 | K9: 2004 | L9: 2005 | M9: 2006 | N9: 2007 | O9: 2008 | P9: 2009 | Q9: 2010 | R9: 2011 | S9: 2012 | T9: 2013 | U9: 2014 | V9: 2015 | W9: 2016 | X9: 2017 | Y9: 2018 | Z9: 2019 | AA9: 2020 | AB9: 2021 | AC9: 2022 | AD9: 2023 | AE9: 2024
A10: European Union - 27 countries (from 2020) | B10: ='total mil euro'!B10/POPULATION!B11*1000000 -> 385.9735 | C10: ='total mil euro'!C10/POPULATION!C11*1000000 -> 412.49164 | D10: ='total mil euro'!D10/POPULATION!D11*1000000 -> 418.11492 | E10: ='total mil euro'!E10/POPULATION!E11*1000000 -> 435.63329 | F10: ='total mil euro'!F10/POPULATION!F11*1000000 -> 465.49466 | G10: ='total mil euro'!G10/POPULATION!G11*1000000 -> 474.86291 | H10: ='total mil euro'!H10/POPULATION!H11*1000000 -> 494.40744 | I10: ='total mil euro'!I10/POPULATION!I11*1000000 -> 515.0966 | ... AE10: ='total mil euro'!AE10/POPULATION!AE11*1000000 -> 834.07902
A11: Belgium | B11: ='total mil euro'!B11/POPULATION!B12*1000000 -> 523.56263 | C11: ='total mil euro'!C11/POPULATION!C12*1000000 -> 576.8523 | D11: ='total mil euro'!D11/POPULATION!D12*1000000 -> 584.57993 | E11: ='total mil euro'!E11/POPULATION!E12*1000000 -> 587.26305 | F11: ='total mil euro'!F11/POPULATION!F12*1000000 -> 615.22935 | G11: ='total mil euro'!G11/POPULATION!G12*1000000 -> 602.29991 | H11: ='total mil euro'!H11/POPULATION!H12*1000000 -> 615.83797 | I11: ='total mil euro'!I11/POPULATION!I12*1000000 -> 620.9283 | ... AE11: ='total mil euro'!AE11/POPULATION!AE12*1000000 -> 1161.3513
A12: Bulgaria | B12: ='total mil euro'!B12/POPULATION!B13*1000000 -> 20.706223 | C12: ='total mil euro'!C12/POPULATION!C13*1000000 -> 9.544749 | D12: ='total mil euro'!D12/POPULATION!D13*1000000 -> 13.910909 | E12: ='total mil euro'!E12/POPULATION!E13*1000000 -> 37.893568 | F12: ='total mil euro'!F12/POPULATION!F13*1000000 -> 38.25587 | G12: ='total mil euro'!G12/POPULATION!G13*1000000 -> 49.02284 | H12: ='total mil euro'!H12/POPULATION!H13*1000000 -> 48.451015 | I12: ='total mil euro'!I12/POPULATION!I13*1000000 -> 52.486937 | ... AE12: ='total mil euro'!AE12/POPULATION!AE13*1000000 -> 480.60804
A13: Czechia | B13: ='total mil euro'!B13/POPULATION!B14*1000000 -> 116.65743 | C13: ='total mil euro'!C13/POPULATION!C14*1000000 -> 125.6939 | D13: ='total mil euro'!D13/POPULATION!D14*1000000 -> 121.46119 | E13: ='total mil euro'!E13/POPULATION!E14*1000000 -> 126.14178 | F13: ='total mil euro'!F13/POPULATION!F14*1000000 -> 138.65817 | G13: ='total mil euro'!G13/POPULATION!G14*1000000 -> 147.0525 | H13: ='total mil euro'!H13/POPULATION!H14*1000000 -> 172.20537 | I13: ='total mil euro'!I13/POPULATION!I14*1000000 -> 194.07653 | ... AE13: ='total mil euro'!AE13/POPULATION!AE14*1000000 -> 425.78016
A14: Denmark | B14: ='total mil euro'!B14/POPULATION!B15*1000000 -> 1169.4325 | C14: ='total mil euro'!C14/POPULATION!C15*1000000 -> 1277.6739 | D14: ='total mil euro'!D14/POPULATION!D15*1000000 -> 1326.017 | E14: ='total mil euro'!E14/POPULATION!E15*1000000 -> 1571.6147 | F14: ='total mil euro'!F14/POPULATION!F15*1000000 -> 1660.0889 | G14: ='total mil euro'!G14/POPULATION!G15*1000000 -> 1614.4292 | H14: ='total mil euro'!H14/POPULATION!H15*1000000 -> 1657.388 | I14: ='total mil euro'!I14/POPULATION!I15*1000000 -> 1767.4319 | ... AE14: ='total mil euro'!AE14/POPULATION!AE15*1000000 -> 1377.354
A15: Germany | B15: ='total mil euro'!B15/POPULATION!B16*1000000 -> 516.06145 | C15: ='total mil euro'!C15/POPULATION!C16*1000000 -> 517.30633 | D15: ='total mil euro'!D15/POPULATION!D16*1000000 -> 506.01836 | E15: ='total mil euro'!E15/POPULATION!E16*1000000 -> 509.36077 | F15: ='total mil euro'!F15/POPULATION!F16*1000000 -> 564.83043 | G15: ='total mil euro'!G15/POPULATION!G16*1000000 -> 620.26344 | H15: ='total mil euro'!H15/POPULATION!H16*1000000 -> 683.34931 | I15: ='total mil euro'!I15/POPULATION!I16*1000000 -> 693.79895 | ... AE15: ='total mil euro'!AE15/POPULATION!AE16*1000000 -> 908.19065
A16: Estonia | B16: ='total mil euro'!B16/POPULATION!B17*1000000 -> 17.685548 | C16: ='total mil euro'!C16/POPULATION!C17*1000000 -> 36.956424 | D16: ='total mil euro'!D16/POPULATION!D17*1000000 -> 48.492314 | E16: ='total mil euro'!E16/POPULATION!E17*1000000 -> 68.488824 | F16: ='total mil euro'!F16/POPULATION!F17*1000000 -> 65.739246 | G16: ='total mil euro'!G16/POPULATION!G17*1000000 -> 74.49777 | H16: ='total mil euro'!H16/POPULATION!H17*1000000 -> 105.80016 | I16: ='total mil euro'!I16/POPULATION!I17*1000000 -> 111.73754 | ... AE16: ='total mil euro'!AE16/POPULATION!AE17*1000000 -> 754.92094
A17: Ireland | B17: ='total mil euro'!B17/POPULATION!B18*1000000 -> 435.04353 | C17: ='total mil euro'!C17/POPULATION!C18*1000000 -> 500.51035 | D17: ='total mil euro'!D17/POPULATION!D18*1000000 -> 588.41217 | E17: ='total mil euro'!E17/POPULATION!E18*1000000 -> 639.22103 | F17: ='total mil euro'!F17/POPULATION!F18*1000000 -> 725.00687 | G17: ='total mil euro'!G17/POPULATION!G18*1000000 -> 787.85143 | H17: ='total mil euro'!H17/POPULATION!H18*1000000 -> 725.20411 | I17: ='total mil euro'!I17/POPULATION!I18*1000000 -> 792.67339 | ... AE17: ='total mil euro'!AE17/POPULATION!AE18*1000000 -> 1028.0004
A18: Greece | B18: ='total mil euro'!B18/POPULATION!B19*1000000 -> 312.43341 | C18: ='total mil euro'!C18/POPULATION!C19*1000000 -> 345.88734 | D18: ='total mil euro'!D18/POPULATION!D19*1000000 -> 351.91985 | E18: ='total mil euro'!E18/POPULATION!E19*1000000 -> 340.01917 | F18: ='total mil euro'!F18/POPULATION!F19*1000000 -> 333.91863 | G18: ='total mil euro'!G18/POPULATION!G19*1000000 -> 296.09228 | H18: ='total mil euro'!H18/POPULATION!H19*1000000 -> 310.07783 | I18: ='total mil euro'!I18/POPULATION!I19*1000000 -> 341.00905 | ... AE18: ='total mil euro'!AE18/POPULATION!AE19*1000000 -> 858.73194
A19: Spain | B19: ='total mil euro'!B19/POPULATION!B20*1000000 -> 251.66698 | C19: ='total mil euro'!C19/POPULATION!C20*1000000 -> 267.50326 | D19: ='total mil euro'!D19/POPULATION!D20*1000000 -> 266.59059 | E19: ='total mil euro'!E19/POPULATION!E20*1000000 -> 304.96308 | F19: ='total mil euro'!F19/POPULATION!F20*1000000 -> 332.77451 | G19: ='total mil euro'!G19/POPULATION!G20*1000000 -> 340.76941 | H19: ='total mil euro'!H19/POPULATION!H20*1000000 -> 348.18173 | I19: ='total mil euro'!I19/POPULATION!I20*1000000 -> 367.75674 | ... AE19: ='total mil euro'!AE19/POPULATION!AE20*1000000 -> 527.42001
A20: France | B20: ='total mil euro'!B20/POPULATION!B21*1000000 -> 515.83779 | C20: ='total mil euro'!C20/POPULATION!C21*1000000 -> 541.95472 | D20: ='total mil euro'!D20/POPULATION!D21*1000000 -> 524.48762 | E20: ='total mil euro'!E20/POPULATION!E21*1000000 -> 546.22897 | F20: ='total mil euro'!F20/POPULATION!F21*1000000 -> 550.49547 | G20: ='total mil euro'!G20/POPULATION!G21*1000000 -> 527.19446 | H20: ='total mil euro'!H20/POPULATION!H21*1000000 -> 492.49487 | I20: ='total mil euro'!I20/POPULATION!I21*1000000 -> 529.04371 | ... AE20: ='total mil euro'!AE20/POPULATION!AE21*1000000 -> 790.96478
A21: Croatia | B21: ='total mil euro'!B21/POPULATION!B22*1000000 -> 118.31351 | C21: ='total mil euro'!C21/POPULATION!C22*1000000 -> 129.05664 | D21: ='total mil euro'!D21/POPULATION!D22*1000000 -> 127.07841 | E21: ='total mil euro'!E21/POPULATION!E22*1000000 -> 144.12103 | F21: ='total mil euro'!F21/POPULATION!F22*1000000 -> 145.98472 | G21: ='total mil euro'!G21/POPULATION!G22*1000000 -> 177.82506 | H21: ='total mil euro'!H21/POPULATION!H22*1000000 -> 212.05679 | I21: ='total mil euro'!I21/POPULATION!I22*1000000 -> 269.17236 | ... AE21: ='total mil euro'!AE21/POPULATION!AE22*1000000 -> 747.17366
... A37: Sweden | B37: ='total mil euro'!B37/POPULATION!B38*1000000 -> 600.28939 | C37: ='total mil euro'!C37/POPULATION!C38*1000000 -> 757.15678 | D37: ='total mil euro'!D37/POPULATION!D38*1000000 -> 742.35861 | E37: ='total mil euro'!E37/POPULATION!E38*1000000 -> 765.24491 | F37: ='total mil euro'!F37/POPULATION!F38*1000000 -> 779.30981 | G37: ='total mil euro'!G37/POPULATION!G38*1000000 -> 836.69039 | H37: ='total mil euro'!H37/POPULATION!H38*1000000 -> 797.20318 | I37: ='total mil euro'!I37/POPULATION!I38*1000000 -> 855.05001 | ... AE37: ='total mil euro'!AE37/POPULATION!AE38*1000000 -> 847.12739

Sheet energy tax euro pers
A1: Data extracted on 30/04/2026 21:21:12 from [ESTAT]
A2: Dataset: | B2: Environmental tax revenues [env_ac_tax__custom_21261132]
A3: Last updated: | B3: 10/02/2026 23:00
A5: Time frequency | B5: Annual
A6: Taxes | B6: Energy taxes
A7: Unit of measure | B7: euro/pers
A9: TIME | B9: 1995 | C9: 1996 | D9: 1997 | E9: 1998 | F9: 1999 | G9: 2000 | H9: 2001 | I9: 2002 | J9: 2003 | K9: 2004 | L9: 2005 | M9: 2006 | N9: 2007 | O9: 2008 | P9: 2009 | Q9: 2010 | R9: 2011 | S9: 2012 | T9: 2013 | U9: 2014 | V9: 2015 | W9: 2016 | X9: 2017 | Y9: 2018 | Z9: 2019 | AA9: 2020 | AB9: 2021 | AC9: 2022 | AD9: 2023 | AE9: 2024
A10: European Union - 27 countries (from 2020) | B10: ='energy tax mil euro'!B10/POPULATION!B11*1000000 -> 295.92464 | C10: ='energy tax mil euro'!C10/POPULATION!C11*1000000 -> 314.45856 | D10: ='energy tax mil euro'!D10/POPULATION!D11*1000000 -> 320.65128 | E10: ='energy tax mil euro'!E10/POPULATION!E11*1000000 -> 330.37731 | F10: ='energy tax mil euro'!F10/POPULATION!F11*1000000 -> 355.10695 | G10: ='energy tax mil euro'!G10/POPULATION!G11*1000000 -> 363.26736 | H10: ='energy tax mil euro'!H10/POPULATION!H11*1000000 -> 379.73639 | I10: ='energy tax mil euro'!I10/POPULATION!I11*1000000 -> 397.75258 | ... AE10: ='energy tax mil euro'!AE10/POPULATION!AE11*1000000 -> 655.32176
A11: Belgium | B11: ='energy tax mil euro'!B11/POPULATION!B12*1000000 -> 326.10492 | C11: ='energy tax mil euro'!C11/POPULATION!C12*1000000 -> 340.14039 | D11: ='energy tax mil euro'!D11/POPULATION!D12*1000000 -> 341.63941 | E11: ='energy tax mil euro'!E11/POPULATION!E12*1000000 -> 348.94504 | F11: ='energy tax mil euro'!F11/POPULATION!F12*1000000 -> 352.33869 | G11: ='energy tax mil euro'!G11/POPULATION!G12*1000000 -> 352.95146 | H11: ='energy tax mil euro'!H11/POPULATION!H12*1000000 -> 353.89784 | I11: ='energy tax mil euro'!I11/POPULATION!I12*1000000 -> 356.32376 | ... AE11: ='energy tax mil euro'!AE11/POPULATION!AE12*1000000 -> 822.86714
A12: Bulgaria | B12: ='energy tax mil euro'!B12/POPULATION!B13*1000000 -> 18.71273 | C12: ='energy tax mil euro'!C12/POPULATION!C13*1000000 -> 8.4296246 | D12: ='energy tax mil euro'!D12/POPULATION!D13*1000000 -> 13.687912 | E12: ='energy tax mil euro'!E12/POPULATION!E13*1000000 -> 36.168389 | F12: ='energy tax mil euro'!F12/POPULATION!F13*1000000 -> 35.684904 | G12: ='energy tax mil euro'!G12/POPULATION!G13*1000000 -> 46.054903 | H12: ='energy tax mil euro'!H12/POPULATION!H13*1000000 -> 45.458182 | I12: ='energy tax mil euro'!I12/POPULATION!I13*1000000 -> 46.49493 | ... AE12: ='energy tax mil euro'!AE12/POPULATION!AE13*1000000 -> 439.8477
A13: Czechia | B13: ='energy tax mil euro'!B13/POPULATION!B14*1000000 -> 94.50835 | C13: ='energy tax mil euro'!C13/POPULATION!C14*1000000 -> 102.91489 | D13: ='energy tax mil euro'!D13/POPULATION!D14*1000000 -> 103.69442 | E13: ='energy tax mil euro'!E13/POPULATION!E14*1000000 -> 109.3054 | F13: ='energy tax mil euro'!F13/POPULATION!F14*1000000 -> 120.09286 | G13: ='energy tax mil euro'!G13/POPULATION!G14*1000000 -> 128.44886 | H13: ='energy tax mil euro'!H13/POPULATION!H14*1000000 -> 153.38603 | I13: ='energy tax mil euro'!I13/POPULATION!I14*1000000 -> 172.39571 | ... AE13: ='energy tax mil euro'!AE13/POPULATION!AE14*1000000 -> 417.76038
A14: Denmark | B14: ='energy tax mil euro'!B14/POPULATION!B15*1000000 -> 566.15024 | C14: ='energy tax mil euro'!C14/POPULATION!C15*1000000 -> 626.05467 | D14: ='energy tax mil euro'!D14/POPULATION!D15*1000000 -> 627.13064 | E14: ='energy tax mil euro'!E14/POPULATION!E15*1000000 -> 793.81325 | F14: ='energy tax mil euro'!F14/POPULATION!F15*1000000 -> 884.62819 | G14: ='energy tax mil euro'!G14/POPULATION!G15*1000000 -> 910.60071 | H14: ='energy tax mil euro'!H14/POPULATION!H15*1000000 -> 981.9465 | I14: ='energy tax mil euro'!I14/POPULATION!I15*1000000 -> 1011.4143 | ... AE14: ='energy tax mil euro'!AE14/POPULATION!AE15*1000000 -> 840.29538
A15: Germany | B15: ='energy tax mil euro'!B15/POPULATION!B16*1000000 -> 425.81181 | C15: ='energy tax mil euro'!C15/POPULATION!C16*1000000 -> 429.42574 | D15: ='energy tax mil euro'!D15/POPULATION!D16*1000000 -> 416.66601 | E15: ='energy tax mil euro'!E15/POPULATION!E16*1000000 -> 415.55251 | F15: ='energy tax mil euro'!F15/POPULATION!F16*1000000 -> 479.0155 | G15: ='energy tax mil euro'!G15/POPULATION!G16*1000000 -> 534.94573 | H15: ='energy tax mil euro'!H15/POPULATION!H16*1000000 -> 581.47663 | I15: ='energy tax mil euro'!I15/POPULATION!I16*1000000 -> 601.61104 | ... AE15: ='energy tax mil euro'!AE15/POPULATION!AE16*1000000 -> 769.85436
A16: Estonia | B16: ='energy tax mil euro'!B16/POPULATION!B17*1000000 -> 11.187266 | C16: ='energy tax mil euro'!C16/POPULATION!C17*1000000 -> 27.252468 | D16: ='energy tax mil euro'!D16/POPULATION!D17*1000000 -> 37.859283 | E16: ='energy tax mil euro'!E16/POPULATION!E17*1000000 -> 57.247497 | F16: ='energy tax mil euro'!F16/POPULATION!F17*1000000 -> 52.579796 | G16: ='energy tax mil euro'!G16/POPULATION!G17*1000000 -> 54.280107 | H16: ='energy tax mil euro'!H16/POPULATION!H17*1000000 -> 79.980183 | I16: ='energy tax mil euro'!I16/POPULATION!I17*1000000 -> 84.343445 | ... AE16: ='energy tax mil euro'!AE16/POPULATION!AE17*1000000 -> 708.36489
A17: Ireland | B17: ='energy tax mil euro'!B17/POPULATION!B18*1000000 -> 246.73833 | C17: ='energy tax mil euro'!C17/POPULATION!C18*1000000 -> 276.60001 | D17: ='energy tax mil euro'!D17/POPULATION!D18*1000000 -> 327.73317 | E17: ='energy tax mil euro'!E17/POPULATION!E18*1000000 -> 354.14116 | F17: ='energy tax mil euro'!F17/POPULATION!F18*1000000 -> 384.38041 | G17: ='energy tax mil euro'!G17/POPULATION!G18*1000000 -> 394.78871 | H17: ='energy tax mil euro'!H17/POPULATION!H18*1000000 -> 374.60248 | I17: ='energy tax mil euro'!I17/POPULATION!I18*1000000 -> 429.26613 | ... AE17: ='energy tax mil euro'!AE17/POPULATION!AE18*1000000 -> 648.81483
A18: Greece | B18: ='energy tax mil euro'!B18/POPULATION!B19*1000000 -> 233.76484 | C18: ='energy tax mil euro'!C18/POPULATION!C19*1000000 -> 253.93896 | D18: ='energy tax mil euro'!D18/POPULATION!D19*1000000 -> 254.09466 | E18: ='energy tax mil euro'!E18/POPULATION!E19*1000000 -> 229.12024 | F18: ='energy tax mil euro'!F18/POPULATION!F19*1000000 -> 216.54543 | G18: ='energy tax mil euro'!G18/POPULATION!G19*1000000 -> 189.37831 | H18: ='energy tax mil euro'!H18/POPULATION!H19*1000000 -> 197.67462 | I18: ='energy tax mil euro'!I18/POPULATION!I19*1000000 -> 205.08301 | ... AE18: ='energy tax mil euro'!AE18/POPULATION!AE19*1000000 -> 696.52702
A19: Spain | B19: ='energy tax mil euro'!B19/POPULATION!B20*1000000 -> 205.34047 | C19: ='energy tax mil euro'!C19/POPULATION!C20*1000000 -> 219.19257 | D19: ='energy tax mil euro'!D19/POPULATION!D20*1000000 -> 218.63746 | E19: ='energy tax mil euro'!E19/POPULATION!E20*1000000 -> 247.14867 | F19: ='energy tax mil euro'!F19/POPULATION!F20*1000000 -> 265.46037 | G19: ='energy tax mil euro'!G19/POPULATION!G20*1000000 -> 270.22364 | H19: ='energy tax mil euro'!H19/POPULATION!H20*1000000 -> 274.63053 | I19: ='energy tax mil euro'!I19/POPULATION!I20*1000000 -> 292.86995 | ... AE19: ='energy tax mil euro'!AE19/POPULATION!AE20*1000000 -> 414.00918
A20: France | B20: ='energy tax mil euro'!B20/POPULATION!B21*1000000 -> 401.31829 | C20: ='energy tax mil euro'!C20/POPULATION!C21*1000000 -> 416.57751 | D20: ='energy tax mil euro'!D20/POPULATION!D21*1000000 -> 416.31483 | E20: ='energy tax mil euro'!E20/POPULATION!E21*1000000 -> 433.45858 | F20: ='energy tax mil euro'!F20/POPULATION!F21*1000000 -> 442.24815 | G20: ='energy tax mil euro'!G20/POPULATION!G21*1000000 -> 434.38749 | H20: ='energy tax mil euro'!H20/POPULATION!H21*1000000 -> 413.41888 | I20: ='energy tax mil euro'!I20/POPULATION!I21*1000000 -> 446.51901 | ... AE20: ='energy tax mil euro'!AE20/POPULATION!AE21*1000000 -> 634.79602
A21: Croatia | B21: ='energy tax mil euro'!B21/POPULATION!B22*1000000 -> 81.270379 | C21: ='energy tax mil euro'!C21/POPULATION!C22*1000000 -> 86.368823 | D21: ='energy tax mil euro'!D21/POPULATION!D22*1000000 -> 86.509503 | E21: ='energy tax mil euro'!E21/POPULATION!E22*1000000 -> 97.848445 | F21: ='energy tax mil euro'!F21/POPULATION!F22*1000000 -> 100.09586 | G21: ='energy tax mil euro'!G21/POPULATION!G22*1000000 -> 134.80341 | H21: ='energy tax mil euro'!H21/POPULATION!H22*1000000 -> 150.27683 | I21: ='energy tax mil euro'!I21/POPULATION!I22*1000000 -> 176.02161 | ... AE21: ='energy tax mil euro'!AE21/POPULATION!AE22*1000000 -> 474.45771
... A37: Sweden | B37: ='energy tax mil euro'!B37/POPULATION!B38*1000000 -> 512.41207 | C37: ='energy tax mil euro'!C37/POPULATION!C38*1000000 -> 644.13155 | D37: ='energy tax mil euro'!D37/POPULATION!D38*1000000 -> 636.1457 | E37: ='energy tax mil euro'!E37/POPULATION!E38*1000000 -> 657.82173 | F37: ='energy tax mil euro'!F37/POPULATION!F38*1000000 -> 664.95323 | G37: ='energy tax mil euro'!G37/POPULATION!G38*1000000 -> 699.05679 | H37: ='energy tax mil euro'!H37/POPULATION!H38*1000000 -> 673.31533 | I37: ='energy tax mil euro'!I37/POPULATION!I38*1000000 -> 723.8778 | ... AE37: ='energy tax mil euro'!AE37/POPULATION!AE38*1000000 -> 622.22918

Sheet transport tax euro pers
A1: Data extracted on 30/04/2026 21:21:12 from [ESTAT]
A2: Dataset: | B2: Environmental tax revenues [env_ac_tax__custom_21261132]
A3: Last updated: | C3: 10/02/2026 23:00
A5: Time frequency | C5: Annual
A6: Taxes | C6: Transport taxes
A7: Unit of measure | C7: euro/pers
A9: TIME | B9: 1995 | C9: 1996 | D9: 1997 | E9: 1998 | F9: 1999 | G9: 2000 | H9: 2001 | I9: 2002 | J9: 2003 | K9: 2004 | L9: 2005 | M9: 2006 | N9: 2007 | O9: 2008 | P9: 2009 | Q9: 2010 | R9: 2011 | S9: 2012 | T9: 2013 | U9: 2014 | V9: 2015 | W9: 2016 | X9: 2017 | Y9: 2018 | Z9: 2019 | AA9: 2020 | AB9: 2021 | AC9: 2022 | AD9: 2023 | AE9: 2024
A10: European Union - 27 countries (from 2020) | B10: ='transport tax mil euro'!B10/POPULATION!B11*1000000 -> 77.542972 | C10: ='transport tax mil euro'!C10/POPULATION!C11*1000000 -> 83.741403 | D10: ='transport tax mil euro'!D10/POPULATION!D11*1000000 -> 83.475906 | E10: ='transport tax mil euro'!E10/POPULATION!E11*1000000 -> 90.182916 | F10: ='transport tax mil euro'!F10/POPULATION!F11*1000000 -> 95.274801 | G10: ='transport tax mil euro'!G10/POPULATION!G11*1000000 -> 94.628042 | H10: ='transport tax mil euro'!H10/POPULATION!H11*1000000 -> 97.320118 | I10: ='transport tax mil euro'!I10/POPULATION!I11*1000000 -> 98.825932 | ... AE10: ='transport tax mil euro'!AE10/POPULATION!AE11*1000000 -> 145.87747
A11: Belgium | B11: ='transport tax mil euro'!B11/POPULATION!B12*1000000 -> 163.26913 | C11: ='transport tax mil euro'!C11/POPULATION!C12*1000000 -> 191.35276 | D11: ='transport tax mil euro'!D11/POPULATION!D12*1000000 -> 190.98789 | E11: ='transport tax mil euro'!E11/POPULATION!E12*1000000 -> 188.01122 | F11: ='transport tax mil euro'!F11/POPULATION!F12*1000000 -> 211.48937 | G11: ='transport tax mil euro'!G11/POPULATION!G12*1000000 -> 202.00047 | H11: ='transport tax mil euro'!H11/POPULATION!H12*1000000 -> 216.56537 | I11: ='transport tax mil euro'!I11/POPULATION!I12*1000000 -> 220.64604 | ... AE11: ='transport tax mil euro'!AE11/POPULATION!AE12*1000000 -> 288.26033
A12: Bulgaria | B12: ='transport tax mil euro'!B12/POPULATION!B13*1000000 -> 1.9163639 | C12: ='transport tax mil euro'!C12/POPULATION!C13*1000000 -> 1.0411803 | D12: ='transport tax mil euro'!D12/POPULATION!D13*1000000 -> 0.20381406 | E12: ='transport tax mil euro'!E12/POPULATION!E13*1000000 -> 1.6611937 | F12: ='transport tax mil euro'!F12/POPULATION!F13*1000000 -> 2.4737645 | G12: ='transport tax mil euro'!G12/POPULATION!G13*1000000 -> 2.8751504 | H12: ='transport tax mil euro'!H12/POPULATION!H13*1000000 -> 2.8762614 | I12: ='transport tax mil euro'!I12/POPULATION!I13*1000000 -> 3.9078311 | ... AE12: ='transport tax mil euro'!AE12/POPULATION!AE13*1000000 -> 36.136946
A13: Czechia | B13: ='transport tax mil euro'!B13/POPULATION!B14*1000000 -> 13.728616 | C13: ='transport tax mil euro'!C13/POPULATION!C14*1000000 -> 15.20054 | D13: ='transport tax mil euro'!D13/POPULATION!D14*1000000 -> 10.702157 | E13: ='transport tax mil euro'!E13/POPULATION!E14*1000000 -> 12.155402 | F13: ='transport tax mil euro'!F13/POPULATION!F14*1000000 -> 14.544753 | G13: ='transport tax mil euro'!G13/POPULATION!G14*1000000 -> 15.195418 | H13: ='transport tax mil euro'!H13/POPULATION!H14*1000000 -> 15.643039 | I13: ='transport tax mil euro'!I13/POPULATION!I14*1000000 -> 18.116528 | ... AE13: ='transport tax mil euro'!AE13/POPULATION!AE14*1000000 -> 5.7409921
A14: Denmark | B14: ='transport tax mil euro'!B14/POPULATION!B15*1000000 -> 544.86075 | C14: ='transport tax mil euro'!C14/POPULATION!C15*1000000 -> 570.2713 | D14: ='transport tax mil euro'!D14/POPULATION!D15*1000000 -> 598.96256 | E14: ='transport tax mil euro'!E14/POPULATION!E15*1000000 -> 657.88708 | F14: ='transport tax mil euro'!F14/POPULATION!F15*1000000 -> 648.65532 | G14: ='transport tax mil euro'!G14/POPULATION!G15*1000000 -> 587.19479 | H14: ='transport tax mil euro'!H14/POPULATION!H15*1000000 -> 560.59659 | I14: ='transport tax mil euro'!I14/POPULATION!I15*1000000 -> 636.82835 | ... AE14: ='transport tax mil euro'!AE14/POPULATION!AE15*1000000 -> 445.37479
A15: Germany | B15: ='transport tax mil euro'!B15/POPULATION!B16*1000000 -> 90.249645 | C15: ='transport tax mil euro'!C15/POPULATION!C16*1000000 -> 87.880589 | D15: ='transport tax mil euro'!D15/POPULATION!D16*1000000 -> 89.352357 | E15: ='transport tax mil euro'!E15/POPULATION!E16*1000000 -> 93.808261 | F15: ='transport tax mil euro'!F15/POPULATION!F16*1000000 -> 85.814926 | G15: ='transport tax mil euro'!G15/POPULATION!G16*1000000 -> 85.317716 | H15: ='transport tax mil euro'!H15/POPULATION!H16*1000000 -> 101.87268 | I15: ='transport tax mil euro'!I15/POPULATION!I16*1000000 -> 92.187913 | ... AE15: ='transport tax mil euro'!AE15/POPULATION!AE16*1000000 -> 138.33629
A16: Estonia | B16: ='transport tax mil euro'!B16/POPULATION!B17*1000000 -> 3.8741087 | C16: ='transport tax mil euro'!C16/POPULATION!C17*1000000 -> 6.378088 | D16: ='transport tax mil euro'!D16/POPULATION!D17*1000000 -> 5.9388505 | E16: ='transport tax mil euro'!E16/POPULATION!E17*1000000 -> 6.080079 | F16: ='transport tax mil euro'!F16/POPULATION!F17*1000000 -> 7.4823979 | G16: ='transport tax mil euro'!G16/POPULATION!G17*1000000 -> 9.3131133 | H16: ='transport tax mil euro'!H16/POPULATION!H17*1000000 -> 10.475903 | I16: ='transport tax mil euro'!I16/POPULATION!I17*1000000 -> 11.145565 | ... AE16: ='transport tax mil euro'!AE16/POPULATION!AE17*1000000 -> 9.0347839
A17: Ireland | B17: ='transport tax mil euro'!B17/POPULATION!B18*1000000 -> 188.3052 | C17: ='transport tax mil euro'!C17/POPULATION!C18*1000000 -> 223.91034 | D17: ='transport tax mil euro'!D17/POPULATION!D18*1000000 -> 260.679 | E17: ='transport tax mil euro'!E17/POPULATION!E18*1000000 -> 285.07987 | F17: ='transport tax mil euro'!F17/POPULATION!F18*1000000 -> 340.62378 | G17: ='transport tax mil euro'!G17/POPULATION!G18*1000000 -> 392.76095 | H17: ='transport tax mil euro'!H17/POPULATION!H18*1000000 -> 350.29899 | I17: ='transport tax mil euro'!I17/POPULATION!I18*1000000 -> 355.83232 | ... AE17: ='transport tax mil euro'!AE17/POPULATION!AE18*1000000 -> 373.63961
A18: Greece | B18: ='transport tax mil euro'!B18/POPULATION!B19*1000000 -> 78.668577 | C18: ='transport tax mil euro'!C18/POPULATION!C19*1000000 -> 91.948382 | D18: ='transport tax mil euro'!D18/POPULATION!D19*1000000 -> 97.824243 | E18: ='transport tax mil euro'!E18/POPULATION!E19*1000000 -> 110.89893 | F18: ='transport tax mil euro'!F18/POPULATION!F19*1000000 -> 117.37228 | G18: ='transport tax mil euro'!G18/POPULATION!G19*1000000 -> 106.71305 | H18: ='transport tax mil euro'!H18/POPULATION!H19*1000000 -> 112.40321 | I18: ='transport tax mil euro'!I18/POPULATION!I19*1000000 -> 135.92604 | ... AE18: ='transport tax mil euro'!AE18/POPULATION!AE19*1000000 -> 159.31357
A19: Spain | B19: ='transport tax mil euro'!B19/POPULATION!B20*1000000 -> 45.605512 | C19: ='transport tax mil euro'!C19/POPULATION!C20*1000000 -> 47.374706 | D19: ='transport tax mil euro'!D19/POPULATION!D20*1000000 -> 46.899366 | E19: ='transport tax mil euro'!E19/POPULATION!E20*1000000 -> 55.359967 | F19: ='transport tax mil euro'!F19/POPULATION!F20*1000000 -> 64.336736 | G19: ='transport tax mil euro'!G19/POPULATION!G20*1000000 -> 67.506492 | H19: ='transport tax mil euro'!H19/POPULATION!H20*1000000 -> 70.305218 | I19: ='transport tax mil euro'!I19/POPULATION!I20*1000000 -> 71.207023 | ... AE19: ='transport tax mil euro'!AE19/POPULATION!AE20*1000000 -> 66.290009
A20: France | B20: ='transport tax mil euro'!B20/POPULATION!B21*1000000 -> 84.775322 | C20: ='transport tax mil euro'!C20/POPULATION!C21*1000000 -> 92.263408 | D20: ='transport tax mil euro'!D20/POPULATION!D21*1000000 -> 81.847912 | E20: ='transport tax mil euro'!E20/POPULATION!E21*1000000 -> 85.862684 | F20: ='transport tax mil euro'!F20/POPULATION!F21*1000000 -> 79.440102 | G20: ='transport tax mil euro'!G20/POPULATION!G21*1000000 -> 59.542467 | H20: ='transport tax mil euro'!H20/POPULATION!H21*1000000 -> 43.719743 | I20: ='transport tax mil euro'!I20/POPULATION!I21*1000000 -> 43.907893 | ... AE20: ='transport tax mil euro'!AE20/POPULATION!AE21*1000000 -> 108.81136
A21: Croatia | B21: ='transport tax mil euro'!B21/POPULATION!B22*1000000 -> 5.4090103 | C21: ='transport tax mil euro'!C21/POPULATION!C22*1000000 -> 9.2247237 | D21: ='transport tax mil euro'!D21/POPULATION!D22*1000000 -> 7.3174046 | E21: ='transport tax mil euro'!E21/POPULATION!E22*1000000 -> 10.826986 | F21: ='transport tax mil euro'!F21/POPULATION!F22*1000000 -> 11.55394 | G21: ='transport tax mil euro'!G21/POPULATION!G22*1000000 -> 10.905489 | H21: ='transport tax mil euro'!H21/POPULATION!H22*1000000 -> 24.428424 | I21: ='transport tax mil euro'!I21/POPULATION!I22*1000000 -> 55.443115 | ... AE21: ='transport tax mil euro'!AE21/POPULATION!AE22*1000000 -> 137.45845
... A37: Sweden | B37: ='transport tax mil euro'!B37/POPULATION!B38*1000000 -> 73.049248 | C37: ='transport tax mil euro'!C37/POPULATION!C38*1000000 -> 92.772885 | D37: ='transport tax mil euro'!D37/POPULATION!D38*1000000 -> 88.727468 | E37: ='transport tax mil euro'!E37/POPULATION!E38*1000000 -> 89.878357 | F37: ='transport tax mil euro'!F37/POPULATION!F38*1000000 -> 96.442167 | G37: ='transport tax mil euro'!G37/POPULATION!G38*1000000 -> 105.01583 | H37: ='transport tax mil euro'!H37/POPULATION!H38*1000000 -> 95.655735 | I37: ='transport tax mil euro'!I37/POPULATION!I38*1000000 -> 102.90682 | ... AE37: ='transport tax mil euro'!AE37/POPULATION!AE38*1000000 -> 193.48054

Sheet pol tax euro pers
A1: Data extracted on 30/04/2026 21:21:12 from [ESTAT]
A2: Dataset: | B2: Environmental tax revenues [env_ac_tax__custom_21261132]
A3: Last updated: | B3: 10/02/2026 23:00
A5: Time frequency | B5: Annual
A6: Taxes | B6: Taxes on pollution/resources
A7: Unit of measure | B7: euro/pers
A9: TIME | B9: 1995 | C9: 1996 | D9: 1997 | E9: 1998 | F9: 1999 | G9: 2000 | H9: 2001 | I9: 2002 | J9: 2003 | K9: 2004 | L9: 2005 | M9: 2006 | N9: 2007 | O9: 2008 | P9: 2009 | Q9: 2010 | R9: 2011 | S9: 2012 | T9: 2013 | U9: 2014 | V9: 2015 | W9: 2016 | X9: 2017 | Y9: 2018 | Z9: 2019 | AA9: 2020 | AB9: 2021 | AC9: 2022 | AD9: 2023 | AE9: 2024
